Workbook
Name _Hlk227065356: '1- DM SP CHUẨN'!$A$5

Sheet BẢNG TÍNH ĐIỂM KPI (LĐB)
A1: BẢNG TÍNH ĐIỂM KPI (Lấy ví dụ mô phỏng chức danh Phó trưởng Ban Tổ chức Thành ủy)
A2: TT | B2: Tên công việc | C2: Điểm chuẩn | D2: Hệ số độ khó | E2: Điểm quy đổi tối đa | F2: Tiến độ % | G2: Kết quả % | H2: Điểm thực hiện | I2: Điểm quy đổi thực tế
A3: 1 | B3: 2 | C3: (3) = Điểm chuẩn của công việc được xác định tại Danh mục Sản phẩm chuẩn | D3: (4) = HSĐK của công việc được xác định tại Danh mục Sản phẩm chuẩn | E3: (5) = (3) *(4) | F3: (6) Căn cứ theo thời hạn hoàn thành + Hoàn thành đúng hoặc trước hạn: 100%; + Hoàn thành chậm 1– 3 ngày làm việc: 80%; + Hoàn thành chậm 4 – 5 ngày làm việc: 60%; + Hoàn thành chậm trên 5 ngày làm việc: 0%. | G3: (7) Căn cứ chất lượng sản phẩm + Đạt đầy đủ yêu cầu: 100%; + Đạt yêu cầu, chỉnh sửa nhỏ: 80%; + Hoàn thành cơ bản: 60%; + Không đạt yêu cầu: 0%. | H3: (8) = (3) * {30% (6)+70%(7)} | I3: (9) = (8)*(4)
A4: I | B4: Trục (1) - THỰC HIỆN MỤC TIÊU PHÁT TRIỂN KINH TẾ - XÃ HỘI VÀ NHIỆM VỤ CHÍNH TRỊ ĐƯỢC GIAO
A5: 2 | B5: Công văn số 1506-CV/BTCTU ngày 23/4/2026 rà soát các khoản chi thường xuyên để điều chỉnh dự toán ngân sách nhà nước năm 2026 (Công văn số 2846-CV/VPTU ngày 17/4/2026) (trước hạn, đạt đầy đủ yêu cầu) | C5: =#REF! -> #REF! | D5: =#REF! -> #REF! | E5: =C5*D5 -> #REF! | F5: 1 | G5: 1 | H5: =C5*(30%*F5+70%*G5) -> #REF! | I5: =D5*H5 -> #REF!
B6: Tổng điểm A trục 1 | C6: =SUM(C5) -> #REF! | G6: Tổng điểm B trục 1 | I6: =MIN(SUM(I5),C6) -> #REF!
B7: KPI % (trục 1) = B/A (nếu không có nhiệm vụ thì KPI được trọn 100%) | C7: =I6/C6 -> #REF! | D7: (Điểm % này được sử dụng để đưa vào cột Điểm KPI (%) tại trục 1, phần II, mẫu 1. Bản tự nhận xét, đánh giá của cá nhân)
A8: II | B8: Trục (2) - HOÀN THIỆN THỂ CHẾ, ĐẨY MẠNH PHÂN CẤP, PHÂN QUYỀN GẮN VỚI KIỂM TRA, GIÁM SÁT
B10: Tổng điểm A trục 2 | C10: =SUM(C9) -> 0 | G10: Tổng điểm B trục 2 | I10: =MIN(SUM(I9),C10) -> 0
B11: KPI % (trục 2) = B/A (nếu không có nhiệm vụ thì KPI được trọn 100%) | C11: =IF(C9=0,1,I9/C9) -> 1 | D11: (Điểm % này được sử dụng để đưa vào cột Điểm KPI (%) tại trục 2, phần II, mẫu 1. Bản tự nhận xét, đánh giá của cá nhân)
A13: III | B13: THÚC ĐẨY PHÁT TRIỂN KHOA HỌC, CÔNG NGHỆ, ĐỔI MỚI SÁNG TẠO VÀ CHUYỂN ĐỔI SỐ
A14: 8 | B14: Công văn số 1461-CV/BTCTU ngày 20/4/2026 về khai thác dữ liệu văn bản điện tử không mật của Thành phố Hồ Chí Minh (cũ), Tỉnh Bình Dương, Tỉnh Bà Rịa - Vũng Tàu trước sáp nhập (Công văn số 2519-CV/VPTU ngày 30/3/2026) (trước hạn, đạt yêu cầu, chỉnh sửa nhỏ) | C14: =#REF! -> #REF! | D14: =#REF! -> #REF! | E14: =C14*D14 -> #REF! | F14: 1 | G14: 0.8 | H14: =C14*(30%*F14+70%*G14) -> #REF! | I14: =D14*H14 -> #REF!
B15: Tổng điểm A trục 3 | C15: =SUM(C14) -> #REF! | G15: Tổng điểm B trục 3 | I15: =MIN(SUM(I14),C15) -> #REF!
B16: KPI % (trục 3) = B/A (nếu không có nhiệm vụ thì KPI được trọn 100%) | C16: =IF(C14=0,1,I14/C14) -> #REF! | D16: (Điểm % này được sử dụng để đưa vào cột Điểm KPI (%) tại trục 3, phần II, mẫu 1. Bản tự nhận xét, đánh giá của cá nhân)
A17: IV | B17: (4) - XÂY DỰNG ĐẢNG VÀ HỆ THỐNG CHÍNH TRỊ TRONG SẠCH, VỮNG MẠNH; GIỮ GÌN ĐOÀN KẾT, THỐNG NHẤT NỘI BỘ; PHÒNG, CHỐNG THAM NHŨNG, LÃNG PHÍ, TIÊU CỰC
A18: 2 | B18: Kế hoạch số 54-KH/TU ngày 06/4/2026 rà soát, bổ sung quy hoạch nguồn Thành ủy khóa I và cán bộ lãnh đạo, quản lý thuộc Thành ủy khóa I, nhiệm kỳ 2025-2030 (trễ hạn >=5 ngày, đạt yêu cầu, chỉnh sửa nhỏ) | C18: =#REF! -> #REF! | D18: =#REF! -> #REF! | E18: =C18*D18 -> #REF! | F18: 0 | G18: 0.8 | H18: =C18*(30%*F18+70%*G18) -> #REF! | I18: =D18*H18 -> #REF!
A19: 7 | B19: Công văn số 1410-CV/BTCTU ngày 14/4/2026 hỗ trợ, cung cấp thông tin quy hoạch các cá nhân thuộc diện Ban Thường vụ Thành ủy quản lý (Công văn số 1706/TTTP-TCCB ngày 09/4/2026 của Thanh tra Thành phố) (trễ hạn >=5 ngày, đạt đầy đủ yêu cầu ) | C19: =#REF! -> #REF! | D19: =#REF! -> #REF! | E19: =C19*D19 -> #REF! | F19: 0 | G19: 1 | H19: =C19*(30%*F19+70%*G19) -> #REF! | I19: =D19*H19 -> #REF!
A20: 13 | B20: Công văn số 294-CV/TU ngày 22/4/2026 triển khai Kết luận số 12-KL/TW, ngày 19/3/2026 của Bộ Chính trị về kết quả kiểm điểm, đánh giá, xếp loại chất lượng đối với tập thể, cá nhân ban thường vụ các tỉnh ủy, thành ủy, đảng ủy trực thuộc Trung ương; tập thể, cá nhân cán bộ lãnh đạo, quản lý các cơ quan, đơn vị ở Trung ương năm 2025 (Phiếu chuyển số 410-PC/VPTU ngày 27/3/2026) (trước hạn, đạt đầy đủ yêu cầu) | C20: =#REF! -> #REF! | D20: =#REF! -> #REF! | E20: =C20*D20 -> #REF! | F20: 1 | G20: 1 | H20: =C20*(30%*F20+70%*G20) -> #REF! | I20: =D20*H20 -> #REF!
A21: 14 | B21: Công văn số 251-CV/TU ngày 31/3/2026 chỉ đạo tiến hành rà soát, đánh giá tổng thể về số lượng, chất lượng đội ngũ cán bộ cơ sở, tổng hợp báo cáo Ban Thường vụ Thành ủy chất lượng đội ngũ cán bộ cơ sở (trước hạn, đạt đầy đủ yêu cầu) | C21: =#REF! -> #REF! | D21: =#REF! -> #REF! | E21: =C21*D21 -> #REF! | F21: 1 | G21: 1 | H21: =C21*(30%*F21+70%*G21) -> #REF! | I21: =D21*H21 -> #REF!
A22: 16 | B22: Công văn số 295-CV/TU ngày 22/4/2026 thực hiện Kết luận số 16-KL/TW, ngày 31/3/2026 của Bộ Chính trị, Ban Bí thư về thực hiện một số nội dung, nhiệm vụ trọng tâm hoạt động của tổ chức cơ sở đảng trong quý II năm 2026 (Phiếu chuyển số 473-PC/VPTU ngay 03/4/2026) (trễ hạn 4-5 ngày, đạt đầy đủ yêu cầu) | C22: =#REF! -> #REF! | D22: =#REF! -> #REF! | E22: =C22*D22 -> #REF! | F22: 0.6 | G22: 1 | H22: =C22*(30%*F22+70%*G22) -> #REF! | I22: =D22*H22 -> #REF!
A23: 17 | B23: Kế hoạch số 62-KH/TU ngày 22/4/2026 tổ chức tiếp Đoàn khảo sát về công tác xây dựng, chỉnh đốn Đảng và hệ thống chính trị; củng cố, nâng cao chất lượng tổ chức đảng và đội ngũ đảng viên (Kế hoạch số 21-KH/BTCTTW ngày 15/4/2026, Phiếu chuyển 559-PC/VPTU ngày 16/4/2026) (đúng hạn, đạt đầy đủ yêu cầu) | C23: =#REF! -> #REF! | D23: =#REF! -> #REF! | E23: =C23*D23 -> #REF! | F23: 1 | G23: 1 | H23: =C23*(30%*F23+70%*G23) -> #REF! | I23: =D23*H23 -> #REF!
A24: 23 | B24: Nghị quyết số 09-NQ/TU ngày 14/4/42026 của Ban Thường vụ Thành ủy về giải pháp nâng cao chất lượng cán bộ cơ sở; bảo đảm mọi giải pháp đều có cơ chế theo dõi, kiểm tra, phản hồi và chịu trách nhiệm (Công văn số 251-CV/TU ngày 31/3/2026) (đúng hạn, đạt đầy đủ yêu cầu) | C24: =#REF! -> #REF! | D24: =#REF! -> #REF! | E24: =C24*D24 -> #REF! | F24: 1 | G24: 1 | H24: =C24*(30%*F24+70%*G24) -> #REF! | I24: =D24*H24 -> #REF!
A25: 39 | B25: Quyết định số 790-QĐ/TU ngày 22/4/2026 tham mưu cử cán bộ đi nghiên cứu, khảo sát tại Trung Quốc (Công văn số 508-CV/BTCTW ngày 03/4/2026, Phiếu chuyển 482-PC/VPTU ngày 06/4/2026) (đúng hạn, đạt yêu cầu, chỉnh sửa nhỏ) | C25: =#REF! -> #REF! | D25: =#REF! -> #REF! | E25: =C25*D25 -> #REF! | F25: 1 | G25: 0.8 | H25: =C25*(30%*F25+70%*G25) -> #REF! | I25: =D25*H25 -> #REF!
A26: 40 | B26: Tờ trình số 539-TTr/BTCTU ngày 21/4/2026 về cử cán bộ tham gia khóa bồi dưỡng ngắn hạn tại Nhật Bản (Công văn số 10-CV/BCĐ ngày 31/3/2026 của Ban Chỉ đạo các chương trình đào tạo, bồi dưỡng nước ngoài Trung ương) (đúng hạn, đạt đầy đủ yêu cầu) | C26: =#REF! -> #REF! | D26: =#REF! -> #REF! | E26: =C26*D26 -> #REF! | F26: 1 | G26: 1 | H26: =C26*(30%*F26+70%*G26) -> #REF! | I26: =D26*H26 -> #REF!
A27: 53 | B27: Công văn số 1308-CV/BTCTU ngày 31/3/2026 xác minh hồ sơ và đề nghị xử lý kỷ luật Đảng viên vi phạm - Hoàng Xuân Tuấn (Công văn số 7970/CQCSĐT, 25/3/2026 của Cơ quan CSĐT CA.TPHCM) (trễ hạn 1 ngày, đạt đầy đủ yêu cầu) | C27: =#REF! -> #REF! | D27: =#REF! -> #REF! | E27: =C27*D27 -> #REF! | F27: 0.8 | G27: 1 | H27: =C27*(30%*F27+70%*G27) -> #REF! | I27: =D27*H27 -> #REF!
A28: 56 | B28: Công văn số 1441-CV/BTCTU ngày 17/4/2026 hướng dẫn rà soát, quy hoạch cán bộ năm 2026 đối với người giữ chức danh, chức vụ quản lý trong doanh nghiệp do Nhà nước nắm giữ 100% vốn điều lệ thuộc Ủy ban nhân dân Thành phố (Công văn số 5812/SNV ngày 09/4/2026 (trước hạn, đạt đầy đủ yêu cầu) | C28: =#REF! -> #REF! | D28: =#REF! -> #REF! | E28: =C28*D28 -> #REF! | F28: 1 | G28: 1 | H28: =C28*(30%*F28+70%*G28) -> #REF! | I28: =D28*H28 -> #REF!
A29: 61 | B29: Công văn số 1496-CV/BTCTU ngày 22/4/2026 báo cáo kinh phí mua vé máy bay đi công tác nước ngoài cho một số chức danh lãnh đạo của Thành phố (Công văn số 2731-CV/VPTU ngày 10/4/2026) (đúng hạn, đạt đầy đủ yêu cầu) | C29: =#REF! -> #REF! | D29: =#REF! -> #REF! | E29: =C29*D29 -> #REF! | F29: 1 | G29: 1 | H29: =C29*(30%*F29+70%*G29) -> #REF! | I29: =D29*H29 -> #REF!
A30: 66 | B30: Công văn số 1459-CV/BTCTU ngày 20/4/2026 cử cán bộ tham gia Đoàn kiểm tra việc lãnh đạo, chỉ đạo và tổ chức thực hiện Kết luận số 89-KL/TW (Công văn số 1234-CV/BTGDVTU ngày 16 tháng 4 năm 2026) (trễ hạn >=5 ngày, đạt đầy đủ yêu cầu) | C30: =#REF! -> #REF! | D30: =#REF! -> #REF! | E30: =C30*D30 -> #REF! | F30: 0 | G30: 1 | H30: =C30*(30%*F30+70%*G30) -> #REF! | I30: =D30*H30 -> #REF!
A31: 68 | B31: Công văn số 1496-CV/BTCTU ngày 22/4/2026 báo cáo kinh phí mua vé máy bay đi công tác nước ngoài cho một số chức danh lãnh đạo của Thành phố (Công văn số 2731-CV/VPTU ngày 10/4/2026) (đúng hạn, đạt đầy đủ yêu cầu) | C31: =#REF! -> #REF! | D31: =#REF! -> #REF! | E31: =C31*D31 -> #REF! | F31: Theo yêu cầu của cấp thẩm quyền | G31: 1 | H31: 1 | I31: =D31*H31 -> #REF!
A32: 78 | B32: Công văn số 303-CV/TU ngày 30/4/2026 góp ý các dự thảo bổ sung, sửa đổi quy định, quyết định của Ban Bí thư (Quy định số 60-QĐ/TW và Quyết định số 61-QĐ/TW) - Công văn số 722-CV/BTCTW ngày 25/4/2026 (trễ hạn1 ngày, đạt yêu cầu, chỉnh sửa nhỏ) | C32: =#REF! -> #REF! | D32: =#REF! -> #REF! | E32: =C32*D32 -> #REF! | F32: 1 | G32: 0.8 | H32: =C32*(30%*F32+70%*G32) -> #REF! | I32: =D32*H32 -> #REF!
A33: 86 | B33: Công văn số 340-CV/TU ngày 21/5/2026 góp ý các dự thảo quy định của Ban Bí thư về chức năng, nhiệm vụ, tổ chức bộ máy, mối quan hệ công tác của tổ chức đảng trong các cơ sở giáo dục đại học công lập theo Công văn số 788-CV/BTCTW ngày 05/5/2026 (Công văn số 3176-CV/VPTU ngày 06/5/2026) (trước hạn, đạt đầy đủ yêu cầu) | C33: =#REF! -> #REF! | D33: =#REF! -> #REF! | E33: =C33*D33 -> #REF! | F33: 1 | G33: 1 | H33: =C33*(30%*F33+70%*G33) -> #REF! | I33: =D33*H33 -> #REF!
A34: 88 | B34: Tham mưu góp ý hồ sơ dự thảo quyết định của UBND Thành phố ban hành quy định về kiểm điểm, dánh giá, xếp loại chất lượng đối với cơ quan hành chính Nhà nước và công chức trên địa bàn TPHCM (đúng hạn, đạt đầy đủ yêu cầu) | C34: =#REF! -> #REF! | D34: =#REF! -> #REF! | E34: =C34*D34 -> #REF! | F34: 1 | G34: 1 | H34: =C34*(30%*F34+70%*G34) -> #REF! | I34: =D34*H34 -> #REF!
A35: 94 | B35: Công văn số 337-CV/TU ngày 19/5/2026 góp ý dự thảo Hướng dẫn nội dung chương trình bồi dưỡng thuộc chức năng, nhiệm vụ của trường chính trị giai đoạn 2026-2030 theo Công văn số 901-CV/HVCTQG ngày 04/5/2026 (Phiếu chuyển số 664-PC/VPTU ngày 05/5/2026) (đúng hạn, đạt đầy đủ yêu cầu) | C35: =#REF! -> #REF! | D35: =#REF! -> #REF! | E35: =C35*D35 -> #REF! | F35: 1 | G35: 1 | H35: =C35*(30%*F35+70%*G35) -> #REF! | I35: =D35*H35 -> #REF!
A36: 95 | B36: Công văn số 333-CV/TU ngày 18/5/2026 góp ý dự thảo Kết luận của Ban Bí thư về tiếp tục thực hiện Chỉ thị số 33-CT/TW, ngày 18/3/2019 của Ban Bí thư về tăng cường xây dựng tổ chức đảng trong các đơn vị kinh tế tư nhân (Phiếu chuyển số 727-PC/VPTU ngày 13/5/2026) (trễ hạn 4 ngày, đạt đầy đủ yêu cầu) | C36: =#REF! -> #REF! | D36: =#REF! -> #REF! | E36: =C36*D36 -> #REF! | F36: 0.6 | G36: 1 | H36: =C36*(30%*F36+70%*G36) -> #REF! | I36: =D36*H36 -> #REF!
A37: 105 | B37: Công văn số 340-CV/TU ngày 21/5/2026 góp ý dự thảo Quy phối hợp công tác giữa đảng ủy bộ, ngành Trung ương với cấp ủy cấp trên trực tiếp của tổ chức đảng trong cơ sở giáo dục đại học công lập (Công văn số 871-CV/BTCTW ngày 12/5/2026 của Ban Tổ chức Trung ương) (trước hạn, đạt đầy đủ yêu cầu) | C37: =#REF! -> #REF! | D37: =#REF! -> #REF! | E37: =C37*D37 -> #REF! | F37: 1 | G37: 1 | H37: =C37*(30%*F37+70%*G37) -> #REF! | I37: =D37*H37 -> #REF!
A38: 108 | B38: Quyết định số 821-QĐ/TU ngày 22/5/2026 tạm giao biên chế năm 2026 của Khối Đảng, Cơ quan Mặt trận Tổ quốc Việt Nam Thành phố; khối Đảng, cơ quan Ủy ban Mặt trận Tổ quốc Việt Nam xã, phường, đặc khu năm 2026 để tiếp nhận một số cán bộ không chuyên trách đủ điều kiện vào công chức (trễ hạn 3ngày, đạt yêu cầu, chỉnh sửa nhỏ) | C38: =#REF! -> #REF! | D38: =#REF! -> #REF! | E38: =C38*D38 -> #REF! | F38: 0.8 | G38: 0.8 | H38: =C38*(30%*F38+70%*G38) -> #REF! | I38: =D38*H38 -> #REF!
A39: 115 | B39: Công văn số 1771-CV/BTCTU ngày 18/5/2026 Hướng dẫn xây dựng Đề án vị trí việc làm công chức, viên chức (trễ hạn 1 ngày, đạt đầy đủ yêu cầu) | C39: =#REF! -> #REF! | D39: =#REF! -> #REF! | E39: =C39*D39 -> #REF! | F39: 0.8 | G39: 1 | H39: =C39*(30%*F39+70%*G39) -> #REF! | I39: =D39*H39 -> #REF!
A40: 131 | B40: Tờ trình số 648-TTr/BTCTU ngày 24/5/2026 báo cáo chuyên đề những điểm mới, mô hình, sáng kiến, cách làm hiệu quả, kết quả nổi bật của TP.HCM sau 1 năm vận hành chính quyền địa phương 2 cấp; đề xuất, kiến nghị (Công văn số 341-CV/TU ngày 21/5/2026) (đúng hạn, đạt đầy đủ yêu cầu) | C40: =#REF! -> #REF! | D40: =#REF! -> #REF! | E40: =C40*D40 -> #REF! | F40: 1 | G40: 1 | H40: =C40*(30%*F40+70%*G40) -> #REF! | I40: =D40*H40 -> #REF!
A41: 132 | B41: Tờ trình số 648-TTr/BTCTU ngày 24/5/2026 Tờ trình số 6454TTr/BTCTU ngày 27/5/2026 về dự thảo Báo cáo của Ban Thường vụ Thành ủy về sơ kết 01 năm vận hành bộ máy của hệ thống chính trị và chính quyền địa phương 2 (Kế hoạch số 73-KH/TU ngày 19/5/2026) (trễ hạn 1 ngày, đạt đầy đủ yêu cầu) | C41: =#REF! -> #REF! | D41: =#REF! -> #REF! | E41: =C41*D41 -> #REF! | F41: 0.8 | G41: 1 | H41: =C41*(30%*F41+70%*G41) -> #REF! | I41: =D41*H41 -> #REF!
A42: 147 | B42: Công văn số 1563-CV/BTCTU ngày 29/4/2026 phúc đáp Công văn số 451/SNV- TCBC&TCPCP ngày 21/4/2026 của Sở Nội vụ (đúng hạn, đạt đầy đủ yêu cầu) | C42: =#REF! -> #REF! | D42: =#REF! -> #REF! | E42: =C42*D42 -> #REF! | F42: 1 | G42: 1 | H42: =C42*(30%*F42+70%*G42) -> #REF! | I42: =D42*H42 -> #REF!
...

Sheet BẢN TỰ ĐÁNH GIÁ (LĐB)
A1: GỢI Ý KHUNG CHẤM ĐIỂM ĐÁNH GIÁ ĐỐI VỚI CÁN BỘ LÃNH ĐẠO, QUẢN LÝ KHỐI ĐẢNG, ĐOÀN THỂ TRÊN CƠ SỞ CỤ THỂ HOÁ THEO MẪU 5,HƯỚNG DẪN SỐ 43-HD/BTCTW CỦA BAN TỔ CHỨC TRUNG ƯƠNG (kèm theo Hướng dẫn số -HD/BTCTU, ngày tháng 6 năm 2026)
H2: Mẫu 01
A3: THÀNH ỦY THÀNH PHỐ HỒ CHÍ MINH BAN TỔ CHỨC * | F3: ĐẢNG CỘNG SẢN VIỆT NAM
F4: …..., ngày…… tháng… … năm……
A5: BẢN TỰ ĐÁNH GIÁ, XẾP LOẠI CỦA CÁ NHÂN (Lấy ví dụ mô phỏng chức danh Phó trưởng Ban Tổ chức Thành ủy)
A6: Quý II, Năm2026
B7: Họ và tên: Nguyễn Văn A Ngày sinh: …..................
B8: Chức vụ Đảng: Thành ủy viên
B9: Chức vụ chính quyền: Phó trưởng ban …..................
B10: Chức vụ đoàn thể: Không có
B11: Đơn vị công tác: …...............
B12: I. Tự đánh giá kết quả thực hiện nhiệm vụ
B13: Trên cơ sở nhiệm vụ được giao, cá nhân tự đánh giá về kết quả thực hiện nhiệm vụ theo quý như sau:
A14: I | B14: NHÓM TIÊU CHÍ CHUNG (30 ĐIỂM) - Các tiêu chí thực hiện theo Quy định sô 366-QĐ/TW của Bộ Chính trị
A15: TT | B15: Tiêu chí / Nội dung | E15: Đảm bảo (Đánh dấu x) | F15: Không đảm bảo (Đánh dấu x) | G15: Điểm tối đa | H15: Điểm đạt (Chấm tối đa nếu đảm bảo; Chấm 0 điểm nếu không đảm bảo) | I15: Ghi chú
A16: 1 | B16: Về phẩm chất chính trị, đạo đức, lối sống, thực hiện trách nhiệm nêu gương | G16: =SUM(G17:G25) -> 18 | H16: =SUM(H17:H25) -> 18
A17: 1.1 | B17: Tuyệt đối trung thành với Đảng, Tổ quốc và Nhân dân; kiên định chủ nghĩa Mác - Lênin, tư tưởng Hồ Chí Minh, mục tiêu độc lập dân tộc và chủ nghĩa xã hội. Có lập trường, quan điểm, bản lĩnh chính trị vững vàng; kiên quyết bảo vệ nền tảng tư tưởng, Cương lĩnh chính trị, đường lối của Đảng, Hiến pháp, pháp luật của Nhà nước; đấu tranh phản bác các quan điểm sai trái, thù địch, các biểu hiện suy thoái, "tự diễn biến", "tự chuyển hoá". | G17: 2 | H17: 2
A18: 1.2 | B18: Có tinh thần yêu nước sâu sắc, tận tuỵ phục vụ Nhân dân, sâu sát cơ sở, luôn hành động vì lợi ích của Nhân dân. Đặt lợi ích của Đảng, quốc gia - dân tộc, Nhân dân, tập thể lên trên lợi ích cá nhân, sẵn sàng hy sinh vì sự nghiệp cách mạng của Đảng, vì độc lập, tự do của Tổ quốc, vì hạnh phúc của Nhân dân. | G18: 2 | H18: 2
A19: 1.3 | B19: Chấp hành nghiêm chủ trương, đường lối, nghị quyết, chỉ thị, quy định, nguyên tắc tổ chức, kỷ luật của Đảng, nhất là nguyên tắc tập trung dân chủ, tự phê bình và phê bình; chấp hành nghiêm pháp luật của Nhà nước và quy định của cơ quan, đơn vị. Tuyệt đối chấp hành sự phân công của tổ chức, yên tâm công tác và hoàn thành tốt mọi nhiệm vụ được giao. | G19: 2 | H19: 2
A20: 1.4 | B20: Có tinh thần tự giác, trách nhiệm cao trong nghiên cứu, học tập chủ nghĩa Mác - Lênin, tư tưởng Hồ Chí Minh, các nghị quyết, chỉ thị của Đảng và các chương trình bồi dưỡng, cập nhật kiến thức mới nhằm nâng cao trình độ về mọi mặt, đáp ứng yêu cầu, nhiệm vụ. | G20: 2 | H20: 2
A21: 1.5 | B21: Có phẩm chất đạo đức, lối sống trong sáng, trung thực, khiêm tốn, chân thành, giản dị; cần, kiệm, liêm, chính, chí công vô tư; chấp hành nghiêm quy định về chuẩn mực đạo đức cách mạng của cán bộ, đảng viên trong giai đoạn mới, trách nhiệm nêu gương; không vi phạm Quy định về những điều đảng viên không được làm. Không né tránh công việc, chạy theo thành tích; không vi phạm đạo đức, lối sống đến mức bị xử lý kỷ luật. | G21: 2 | H21: 2
A22: 1.6 | B22: Không tham vọng quyền lực; không chạy chức, chạy quyền; không tham nhũng, lãng phí, cơ hội, vụ lợi, cục bộ, lợi ích nhóm; không để gia đình, người thân và người khác lợi dụng chức vụ, vị trí công tác để trục lợi. Không có biểu hiện suy thoái về tư tưởng chính trị, đạo đức, lối sống, những biểu hiện "tự diễn biến", "tự chuyển hoá" trong nội bộ. Kiên quyết đấu tranh chống quan liêu, cửa quyền, tham nhũng, xa hoa, lãng phí, tiêu cực, chủ nghĩa cá nhân, lối sống cơ hội, thực dụng, bè phái, lợi ích nhóm, nói không đi đôi với làm. | G22: 2 | H22: 2
A23: 1.7 | B23: Có uy tín cao, tiêu biểu về phẩm chất đạo đức và phong cách công tác; là trung tâm đoàn kết, thương yêu đồng chí, đồng nghiệp. | G23: 2 | H23: 2
A24: 1.8 | B24: Có tinh thần chủ động, đổi mới sáng tạo; phấn đấu vì mục tiêu phát triển của cơ quan, đơn vị, đóng góp vào mục tiêu chung của đất nước. | G24: 2 | H24: 2
A25: 1.9 | B25: Thực hiện việc kê khai và công khai tài sản, thu nhập theo quy định. Báo cáo đầy đủ, trung thực, cung cấp thông tin chính xác, khách quan về những nội dung liên quan đến việc thực hiện chức trách, nhiệm vụ được giao và hoạt động của cơ quan, tổ chức, đơn vị với cấp trên khi được yêu cầu. | G25: 2 | H25: 2
A26: 2 | B26: Tư duy đổi mới, chiến lược, khát vọng cống hiến, dám nghĩ, dám làm | G26: =SUM(G27:G30) -> 4 | H26: =SUM(H27:H30) -> 4
A27: 2.1 | B27: Có tư duy đổi mới, tầm nhìn chiến lược, khả năng lãnh đạo, chỉ đạo thích ứng với sự phát triển của thời đại và xu thế toàn cầu hoá; phương pháp làm việc khoa học, nhạy bén chính trị; có năng lực cụ thể hoá trong lãnh đạo, chỉ đạo cơ quan, đơn vị thực hiện và hoàn thành tốt chức năng, nhiệm vụ được giao. | G27: 1 | H27: 1
A28: 2.2 | B28: Luôn bám sát thực tiễn, có nhiều cách làm hay, sáng tạo, đạt hiệu quả cao trong lãnh đạo, chỉ đạo, tổ chức thực hiện nhiệm vụ; xây dựng cấp uỷ, tổ chức đảng trong sạch, vững mạnh, cơ quan, đơn vị vững mạnh toàn diện. | G28: 1 | H28: 1
A29: 2.3 | B29: Nói đi đôi với làm, dám nghĩ, dám làm, dám chịu trách nhiệm, dám đột phá vì lợi ích chung. Có khả năng phân tích, dự báo tình hình, phát hiện những khó khăn, bất cập, thời cơ, thuận lợi trong thực tiễn; đề xuất hoặc quyết định những giải pháp phù hợp, kịp thời, hiệu quả. | G29: 1 | H29: 1
A30: 2.4 | B30: Có khát vọng phấn đấu, cống hiến; có khả năng quy tụ và phát huy được sức mạnh của tập thể, cá nhân trong cơ quan, đơn vị và các cơ quan, đơn vị có liên quan. | G30: 1 | H30: 1
B31: 3. Về tự phê bình và phê bình, tự soi, tự sửa, khắc phục hạn chế, khuyết điểm | G31: =SUM(G32:G35) -> 8 | H31: =SUM(H32:H35) -> 8
A32: 3.1 | B32: Chủ động, nghiêm túc thực hiện tự phê bình và phê bình, có tinh thần cầu thị và tiếp thu phản biện, góp ý. | G32: 2 | H32: 2
A33: 3.2 | B33: Có kế hoạch rõ ràng và quyết liệt trong khắc phục hạn chế, khuyết điểm đã được chỉ ra. | G33: 2 | H33: 2
A34: 3.3 | B34: Kết quả khắc phục hoàn thành từ ≥ 80% nội dung, có tiến bộ rõ, được tổ chức đánh giá tốt; không để tái diễn tồn tại. | G34: 2 | H34: 2
A35: 3.4 | B35: Tự soi, tự sửa trên tinh thần trách nhiệm chính trị cao, không né tránh, không đổ lỗi. | G35: 2 | H35: 2
A36: Tổng (A) = | G36: =SUM(G31,G26,G16) -> 30 | H36: =SUM(H31,H26,H16) -> 30
A37: B | B37: KẾT QUẢ THỰC HIỆN NHIỆM VỤ ĐƯỢC GIAO (70 ĐIỂM) | G37: Điểm tối đa | H37: Điểm đạt được = điểm KPI đã tính tại Bảng tính điểm
A38: TT | B38: Tiêu chí / Nội dung | D38: Mục tiêu, nhiệm vụ đề ra | E38: Kết quả sản phẩm thực tế | F38: Điểm KPI (%) | G38: Điểm tối đa | H38: Điểm đạt (= Điểm KPI x Điểm tối đa) | I38: Ghi chú
A39: 1 | B39: Trục (1) - THỰC HIỆN MỤC TIÊU PHÁT TRIỂN KINH TẾ - XÃ HỘI VÀ NHIỆM VỤ CHÍNH TRỊ ĐƯỢC GIAO (10 ĐIỂM) - Lãnh đạo, chỉ đạo, điều hành, tổ chức thực hiện hiệu quả nghị quyết, chỉ thị, kết luận, quy định, hướng dẫn của Trung ương và cấp trên. - Chủ động xây dựng và lãnh đạo, chỉ đạo thực hiện có hiệu quả kế hoạch, chương trình công tác, đề án, quy chế, quy định thuộc lĩnh vực phụ trách gắn với kế hoạch, chương trình công tác và tình hình thực tiễn của tổ chức, cơ quan, đơn vị. - Phân tích, tổng hợp, đánh giá và tham mưu cấp uỷ ban hành các văn bản theo lĩnh vực công tác đạt yêu cầu về nội dung, hình thức và tiến độ; - Các nội dung khác (nếu có) | G39: 10 | H39: =F39*G39 -> 0
A40: 2 | B40: Trục (2) - HOÀN THIỆN THỂ CHẾ, ĐẨY MẠNH PHÂN CẤP, PHÂN QUYỀN GẮN VỚI KIỂM TRA, GIÁM SÁT (15 ĐIỂM) - Ban hành kế hoạch, chương trình hành động thực hiện các nghị quyết, chỉ thị, kết luận theo phân cấp - Triển khai, quán triệt chính sách phân cấp - Giám sát thực hiện phân quyền - Hướng dẫn và tổ chức kiểm tra, giám sát việc thực hiện nhiệm vụ theo lĩnh vực được phân công, góp phần ngăn ngừa khuyết điểm, vi phạm, kịp thời phát hiện và xử lý các vấn đề phát sinh (nếu có); - Xử lý điểm nghẽn thể chế, cải cách hành chính: Có sáng kiến/giải pháp cụ thể được cấp có thẩm quyền ghi nhận; - Tỉ lệ hồ sơ giải quyết đúng hạn; - Giải quyết 100% đơn, thư thuộc trách nhiệm, không để vượt cấp, phát sinh kéo dài; - Nội dung khác (nếu có) | G40: 15 | H40: =F40*G40 -> 0
...

Sheet 1- DM SP CHUẨN
A1: ĐẢNG ỦY PHƯỜNG AN ĐÔNG TRƯỜNG MẦM NON HOÀNG YẾN | F1: ĐẢNG CỘNG SẢN VIỆT NAM
F2: An Đông, ngày 08 tháng 9 năm 2026
A4: DANH MỤC SẢN PHẨM CHUẨN QUÝ III NĂM 2026
A5: TT | B5: Tên công việc | C5: Kết quả đầu ra | D5: Thời hạn hoàn thành | E5: Loại công việc | F5: Điểm chuẩn | G5: Hệ số độ khó | H5: Điểm quy đổi tối đa | I5: Minh chứng
A6: 1 | B6: 2 | C6: 3 | D6: 4 | E6: 5 | F6: 6 | G6: 7 | H6: 8 | I6: 9
A7: I | B7: TRỤC 1 - THỰC HIỆN MỤC TIÊU PHÁT TRIỂN KINH TẾ - XÃ HỘI VÀ NHIỆM VỤ CHÍNH TRỊ ĐƯỢC GIAO
A8: 1 | H8: =G8*F8 -> 0
A9: 2 | H9: =G9*F9 -> 0
A10: 3 | H10: =G10*F10 -> 0
A11: 4 | H11: =G11*F11 -> 0
A12: 5 | H12: =G12*F12 -> 0
A13: 6 | H13: =G13*F13 -> 0
A14: 7 | H14: =G14*F14 -> 0
A15: 8 | H15: =G15*F15 -> 0
A16: 9 | H16: =G16*F16 -> 0
A17: 10 | H17: =G17*F17 -> 0
A18: 11 | H18: =G18*F18 -> 0
A19: 12 | H19: =G19*F19 -> 0
... A47: 40 | H47: =G47*F47 -> 0
A48: II. | B48: TRỤC 2 - HOÀN THIỆN THỂ CHẾ, ĐẨY MẠNH PHÂN CẤP, PHÂN QUYỀN GẮN VỚI KIỂM TRA, GIÁM SÁT
A49: 1 | H49: =G49*F49 -> 0
A50: 2 | H50: =G50*F50 -> 0
A51: 3 | H51: =G51*F51 -> 0
A52: 4 | H52: =G52*F52 -> 0
A53: 5 | H53: =G53*F53 -> 0
A54: III | B54: TRỤC 3 - THÚC ĐẨY PHÁT TRIỂN KHOA HỌC, CÔNG NGHỆ, ĐỔI MỚI SÁNG TẠO VÀ CHUYỂN ĐỔI SỐ
A55: 1 | H55: =G55*F55 -> 0
A56: 2 | H56: =G56*F56 -> 0
A57: 3 | H57: =G57*F57 -> 0
A58: 4 | H58: =G58*F58 -> 0
A59: 5 | H59: =G59*F59 -> 0
A60: IV | B60: TRỤC 4 - XÂY DỰNG ĐẢNG VÀ HỆ THỐNG CHÍNH TRỊ TRONG SẠCH, VỮNG MẠNH; GIỮ GÌN ĐOÀN KẾT, THỐNG NHẤT NỘI BỘ; PHÒNG, CHỐNG THAM NHŨNG, LÃNG PHÍ, TIÊU CỰC
A61: 1 | H61: =G61*F61 -> 0
A62: 2 | H62: =G62*F62 -> 0
A63: 3 | H63: =G63*F63 -> 0
A64: 4 | H64: =G64*F64 -> 0
A65: 5 | H65: =G65*F65 -> 0
A66: V | B66: TRỤC 5 - PHÁT TRIỂN VĂN HÓA, CON NGƯỜI, BẢO ĐẢM AN SINH XÃ HỘI, NÂNG CAO ĐỜI SỐNG NHÂN DÂN
A67: 1 | H67: =G67*F67 -> 0
A68: 2 | H68: =G68*F68 -> 0
...

Sheet 2 - BẢNG TÍNH KPI 
A1: ĐẢNG ỦY PHƯỜNG AN ĐÔNG TRƯỜNG MẦM NON HOÀNG YẾN | F1: ĐẢNG CỘNG SẢN VIỆT NAM
F2: An Đông, ngày 08 tháng 9 năm 2026
A3: BẢNG TÍNH ĐIỂM KPI
A4: TT | B4: Tên công việc | C4: Điểm chuẩn | D4: Hệ số độ khó | E4: Điểm quy đổi tối đa | F4: Tiến độ % | G4: Kết quả % | H4: Điểm thực hiện | I4: Điểm quy đổi thực tế
A5: 1 | B5: 2 | C5: (3) = Điểm chuẩn của công việc được xác định tại Danh mục Sản phẩm chuẩn | D5: (4) = HSĐK của công việc được xác định tại Danh mục Sản phẩm chuẩn | E5: (5) = (3) *(4) | F5: (6) Căn cứ theo thời hạn hoàn thành + Hoàn thành đúng hoặc trước hạn: 100%; + Hoàn thành chậm 1– 3 ngày làm việc: 80%; + Hoàn thành chậm 4 – 5 ngày làm việc: 60%; + Hoàn thành chậm trên 5 ngày làm việc: 0%. | G5: (7) Căn cứ chất lượng sản phẩm + Đạt đầy đủ yêu cầu: 100%; + Đạt yêu cầu, chỉnh sửa nhỏ: 80%; + Hoàn thành cơ bản: 60%; + Không đạt yêu cầu: 0%. | H5: (8) = (3) * {30% (6)+70%(7)} | I5: (9) = (8)*(4)
A6: I | B6: TRỤC 1 - THỰC HIỆN MỤC TIÊU PHÁT TRIỂN KINH TẾ - XÃ HỘI VÀ NHIỆM VỤ CHÍNH TRỊ ĐƯỢC GIAO
A7: 1 | B7: ='1- DM SP CHUẨN'!B8 -> 0 | C7: ='1- DM SP CHUẨN'!F8 -> 0 | D7: ='1- DM SP CHUẨN'!G8 -> 0 | E7: =C7*D7 -> 0 | H7: =C7*(30%*F7+70%*G7) -> 0 | I7: =H7*D7 -> 0
A8: 2 | B8: ='1- DM SP CHUẨN'!B9 -> 0 | C8: ='1- DM SP CHUẨN'!F9 -> 0 | D8: ='1- DM SP CHUẨN'!G9 -> 0 | E8: =C8*D8 -> 0 | H8: =C8*(30%*F8+70%*G8) -> 0 | I8: =H8*D8 -> 0
A9: 3 | B9: ='1- DM SP CHUẨN'!B10 -> 0 | C9: ='1- DM SP CHUẨN'!F10 -> 0 | D9: ='1- DM SP CHUẨN'!G10 -> 0 | E9: =C9*D9 -> 0 | H9: =C9*(30%*F9+70%*G9) -> 0 | I9: =H9*D9 -> 0
A10: 4 | B10: ='1- DM SP CHUẨN'!B11 -> 0 | C10: ='1- DM SP CHUẨN'!F11 -> 0 | D10: ='1- DM SP CHUẨN'!G11 -> 0 | E10: =C10*D10 -> 0 | H10: =C10*(30%*F10+70%*G10) -> 0 | I10: =H10*D10 -> 0
A11: 5 | B11: ='1- DM SP CHUẨN'!B12 -> 0 | C11: ='1- DM SP CHUẨN'!F12 -> 0 | D11: ='1- DM SP CHUẨN'!G12 -> 0 | E11: =C11*D11 -> 0 | H11: =C11*(30%*F11+70%*G11) -> 0 | I11: =H11*D11 -> 0
A12: 6 | B12: ='1- DM SP CHUẨN'!B13 -> 0 | C12: ='1- DM SP CHUẨN'!F13 -> 0 | D12: ='1- DM SP CHUẨN'!G13 -> 0 | E12: =C12*D12 -> 0 | H12: =C12*(30%*F12+70%*G12) -> 0 | I12: =H12*D12 -> 0
A13: 7 | B13: ='1- DM SP CHUẨN'!B14 -> 0 | C13: ='1- DM SP CHUẨN'!F14 -> 0 | D13: ='1- DM SP CHUẨN'!G14 -> 0 | E13: =C13*D13 -> 0 | H13: =C13*(30%*F13+70%*G13) -> 0 | I13: =H13*D13 -> 0
A14: 8 | B14: ='1- DM SP CHUẨN'!B15 -> 0 | C14: ='1- DM SP CHUẨN'!F15 -> 0 | D14: ='1- DM SP CHUẨN'!G15 -> 0 | E14: =C14*D14 -> 0 | H14: =C14*(30%*F14+70%*G14) -> 0 | I14: =H14*D14 -> 0
A15: 9 | B15: ='1- DM SP CHUẨN'!B16 -> 0 | C15: ='1- DM SP CHUẨN'!F16 -> 0 | D15: ='1- DM SP CHUẨN'!G16 -> 0 | E15: =C15*D15 -> 0 | H15: =C15*(30%*F15+70%*G15) -> 0 | I15: =H15*D15 -> 0
A16: 10 | B16: ='1- DM SP CHUẨN'!B17 -> 0 | C16: ='1- DM SP CHUẨN'!F17 -> 0 | D16: ='1- DM SP CHUẨN'!G17 -> 0 | E16: =C16*D16 -> 0 | H16: =C16*(30%*F16+70%*G16) -> 0 | I16: =H16*D16 -> 0
A17: 11 | B17: ='1- DM SP CHUẨN'!B18 -> 0 | C17: ='1- DM SP CHUẨN'!F18 -> 0 | D17: ='1- DM SP CHUẨN'!G18 -> 0 | E17: =C17*D17 -> 0 | H17: =C17*(30%*F17+70%*G17) -> 0 | I17: =H17*D17 -> 0
A18: 12 | B18: ='1- DM SP CHUẨN'!B19 -> 0 | C18: ='1- DM SP CHUẨN'!F19 -> 0 | D18: ='1- DM SP CHUẨN'!G19 -> 0 | E18: =C18*D18 -> 0 | H18: =C18*(30%*F18+70%*G18) -> 0 | I18: =H18*D18 -> 0
... A46: 40 | B46: ='1- DM SP CHUẨN'!B47 -> 0 | C46: ='1- DM SP CHUẨN'!F47 -> 0 | D46: ='1- DM SP CHUẨN'!G47 -> 0 | E46: =C46*D46 -> 0 | H46: =C46*(30%*F46+70%*G46) -> 0 | I46: =H46*D46 -> 0
A47: II. | B47: TRỤC 2 - HOÀN THIỆN THỂ CHẾ, ĐẨY MẠNH PHÂN CẤP, PHÂN QUYỀN GẮN VỚI KIỂM TRA, GIÁM SÁT
A49: 1 | B49: ='1- DM SP CHUẨN'!B49 -> 0 | C49: ='1- DM SP CHUẨN'!F49 -> 0 | D49: ='1- DM SP CHUẨN'!G49 -> 0 | E49: =C49*D49 -> 0 | H49: =C49*(30%*F49+70%*G49) -> 0 | I49: =H49*D49 -> 0
A50: 2 | B50: ='1- DM SP CHUẨN'!B50 -> 0 | C50: ='1- DM SP CHUẨN'!F50 -> 0 | D50: ='1- DM SP CHUẨN'!G50 -> 0 | E50: =C50*D50 -> 0 | H50: =C50*(30%*F50+70%*G50) -> 0 | I50: =H50*D50 -> 0
A51: 3 | B51: ='1- DM SP CHUẨN'!B51 -> 0 | C51: ='1- DM SP CHUẨN'!F51 -> 0 | D51: ='1- DM SP CHUẨN'!G51 -> 0 | E51: =C51*D51 -> 0 | H51: =C51*(30%*F51+70%*G51) -> 0 | I51: =H51*D51 -> 0
A52: 4 | B52: ='1- DM SP CHUẨN'!B52 -> 0 | C52: ='1- DM SP CHUẨN'!F52 -> 0 | D52: ='1- DM SP CHUẨN'!G52 -> 0 | E52: =C52*D52 -> 0 | H52: =C52*(30%*F52+70%*G52) -> 0 | I52: =H52*D52 -> 0
A53: 5 | B53: ='1- DM SP CHUẨN'!B53 -> 0 | C53: ='1- DM SP CHUẨN'!F53 -> 0 | D53: ='1- DM SP CHUẨN'!G53 -> 0 | E53: =C53*D53 -> 0 | H53: =C53*(30%*F53+70%*G53) -> 0 | I53: =H53*D53 -> 0
A54: III | B54: TRỤC 3 - THÚC ĐẨY PHÁT TRIỂN KHOA HỌC, CÔNG NGHỆ, ĐỔI MỚI SÁNG TẠO VÀ CHUYỂN ĐỔI SỐ
A55: 1 | B55: ='1- DM SP CHUẨN'!B55 -> 0 | C55: ='1- DM SP CHUẨN'!F55 -> 0 | D55: ='1- DM SP CHUẨN'!G55 -> 0 | E55: =C55*D55 -> 0 | H55: =C55*(30%*F55+70%*G55) -> 0 | I55: =H55*D55 -> 0
A56: 2 | B56: ='1- DM SP CHUẨN'!B56 -> 0 | C56: ='1- DM SP CHUẨN'!F56 -> 0 | D56: ='1- DM SP CHUẨN'!G56 -> 0 | E56: =C56*D56 -> 0 | H56: =C56*(30%*F56+70%*G56) -> 0 | I56: =H56*D56 -> 0
A57: 3 | B57: ='1- DM SP CHUẨN'!B57 -> 0 | C57: ='1- DM SP CHUẨN'!F57 -> 0 | D57: ='1- DM SP CHUẨN'!G57 -> 0 | E57: =C57*D57 -> 0 | H57: =C57*(30%*F57+70%*G57) -> 0 | I57: =H57*D57 -> 0
A58: 4 | B58: ='1- DM SP CHUẨN'!B58 -> 0 | C58: ='1- DM SP CHUẨN'!F58 -> 0 | D58: ='1- DM SP CHUẨN'!G58 -> 0 | E58: =C58*D58 -> 0 | H58: =C58*(30%*F58+70%*G58) -> 0 | I58: =H58*D58 -> 0
A59: 5 | B59: ='1- DM SP CHUẨN'!B59 -> 0 | C59: ='1- DM SP CHUẨN'!F59 -> 0 | D59: ='1- DM SP CHUẨN'!G59 -> 0 | E59: =C59*D59 -> 0 | H59: =C59*(30%*F59+70%*G59) -> 0 | I59: =H59*D59 -> 0
A60: IV | B60: TRỤC 4 - XÂY DỰNG ĐẢNG VÀ HỆ THỐNG CHÍNH TRỊ TRONG SẠCH, VỮNG MẠNH; GIỮ GÌN ĐOÀN KẾT, THỐNG NHẤT NỘI BỘ; PHÒNG, CHỐNG THAM NHŨNG, LÃNG PHÍ, TIÊU CỰC
A61: 1 | B61: ='1- DM SP CHUẨN'!B61 -> 0 | C61: ='1- DM SP CHUẨN'!F61 -> 0 | D61: ='1- DM SP CHUẨN'!G61 -> 0 | E61: =C61*D61 -> 0 | H61: =C61*(30%*F61+70%*G61) -> 0 | I61: =H61*D61 -> 0
A62: 2 | B62: ='1- DM SP CHUẨN'!B62 -> 0 | C62: ='1- DM SP CHUẨN'!F62 -> 0 | D62: ='1- DM SP CHUẨN'!G62 -> 0 | E62: =C62*D62 -> 0 | H62: =C62*(30%*F62+70%*G62) -> 0 | I62: =H62*D62 -> 0
A63: 3 | B63: ='1- DM SP CHUẨN'!B63 -> 0 | C63: ='1- DM SP CHUẨN'!F63 -> 0 | D63: ='1- DM SP CHUẨN'!G63 -> 0 | E63: =C63*D63 -> 0 | H63: =C63*(30%*F63+70%*G63) -> 0 | I63: =H63*D63 -> 0
A64: 4 | B64: ='1- DM SP CHUẨN'!B64 -> 0 | C64: ='1- DM SP CHUẨN'!F64 -> 0 | D64: ='1- DM SP CHUẨN'!G64 -> 0 | E64: =C64*D64 -> 0 | H64: =C64*(30%*F64+70%*G64) -> 0 | I64: =H64*D64 -> 0
A65: 5 | B65: ='1- DM SP CHUẨN'!B65 -> 0 | C65: ='1- DM SP CHUẨN'!F65 -> 0 | D65: ='1- DM SP CHUẨN'!G65 -> 0 | E65: =C65*D65 -> 0 | H65: =C65*(30%*F65+70%*G65) -> 0 | I65: =H65*D65 -> 0
A66: V | B66: TRỤC 5 - PHÁT TRIỂN VĂN HÓA, CON NGƯỜI, BẢO ĐẢM AN SINH XÃ HỘI, NÂNG CAO ĐỜI SỐNG NHÂN DÂN
A67: 1 | B67: ='1- DM SP CHUẨN'!B67 -> 0 | C67: ='1- DM SP CHUẨN'!F67 -> 0 | D67: ='1- DM SP CHUẨN'!G67 -> 0 | E67: =C67*D67 -> 0 | H67: =C67*(30%*F67+70%*G67) -> 0 | I67: =H67*D67 -> 0
A68: 2 | B68: ='1- DM SP CHUẨN'!B68 -> 0 | C68: ='1- DM SP CHUẨN'!F68 -> 0 | D68: ='1- DM SP CHUẨN'!G68 -> 0 | E68: =C68*D68 -> 0 | H68: =C68*(30%*F68+70%*G68) -> 0 | I68: =H68*D68 -> 0
...

Sheet 3 - MẪU TỰ ĐÁNH GIÁ LD, QL
H1: Mẫu 01-A
A2: THÀNH ỦY/ĐẢNG ỦY/ CƠ QUAN, ĐƠN VỊ… * | F2: ĐẢNG CỘNG SẢN VIỆT NAM
F3: …..., ngày…… tháng… … năm……
A4: BẢN TỰ ĐÁNH GIÁ, XẾP LOẠI CỦA CÁ NHÂN
A5: Quý …., Năm ….
B6: Họ và tên:…………………………..………................................................................... Ngày sinh: ………………………...................................................
B7: Chức vụ Đảng: ……………………………………………………………….……………………………………………………………….……………….
B8: Chức vụ chính quyền: ………………………………………………………..……………………………………………………………….……………….
B9: Chức vụ đoàn thể: …………………………………………………………………………………………………………………………….………………
B10: Đơn vị công tác: ……………………………...……………………………………………………………………………………………….………………
B11: I. Tự đánh giá kết quả thực hiện nhiệm vụ
B12: Trên cơ sở nhiệm vụ được giao, cá nhân tự đánh giá về kết quả thực hiện nhiệm vụ theo quý như sau:
A13: A | B13: NHÓM TIÊU CHÍ CHUNG (30 ĐIỂM)
A14: TT | B14: Tiêu chí / Nội dung | E14: Đảm bảo (Đánh dấu x) | F14: Không đảm bảo (Đánh dấu x) | G14: Điểm tối đa | H14: Điểm đạt (Chấm tối đa nếu đảm bảo; Chấm 0 điểm nếu không đảm bảo) | I14: Ghi chú
A15: 1 | B15: Về phẩm chất chính trị, đạo đức, lối sống, thực hiện trách nhiệm nêu gương | G15: =SUM(G16:G24) -> 18 | H15: =SUM(H16:H24) -> 0
A16: 1.1 | B16: Tuyệt đối trung thành với Đảng, Tổ quốc và Nhân dân; kiên định chủ nghĩa Mác - Lênin, tư tưởng Hồ Chí Minh, mục tiêu độc lập dân tộc và chủ nghĩa xã hội. Có lập trường, quan điểm, bản lĩnh chính trị vững vàng; kiên quyết bảo vệ nền tảng tư tưởng, Cương lĩnh chính trị, đường lối của Đảng, Hiến pháp, pháp luật của Nhà nước; đấu tranh phản bác các quan điểm sai trái, thù địch, các biểu hiện suy thoái, "tự diễn biến", "tự chuyển hoá". | G16: 2
A17: 1.2 | B17: Có tinh thần yêu nước sâu sắc, tận tuỵ phục vụ Nhân dân, sâu sát cơ sở, luôn hành động vì lợi ích của Nhân dân. Đặt lợi ích của Đảng, quốc gia - dân tộc, Nhân dân, tập thể lên trên lợi ích cá nhân, sẵn sàng hy sinh vì sự nghiệp cách mạng của Đảng, vì độc lập, tự do của Tổ quốc, vì hạnh phúc của Nhân dân. | G17: 2
A18: 1.3 | B18: Chấp hành nghiêm chủ trương, đường lối, nghị quyết, chỉ thị, quy định, nguyên tắc tổ chức, kỷ luật của Đảng, nhất là nguyên tắc tập trung dân chủ, tự phê bình và phê bình; chấp hành nghiêm pháp luật của Nhà nước và quy định của cơ quan, đơn vị. Tuyệt đối chấp hành sự phân công của tổ chức, yên tâm công tác và hoàn thành tốt mọi nhiệm vụ được giao. | G18: 2
A19: 1.4 | B19: Có tinh thần tự giác, trách nhiệm cao trong nghiên cứu, học tập chủ nghĩa Mác - Lênin, tư tưởng Hồ Chí Minh, các nghị quyết, chỉ thị của Đảng và các chương trình bồi dưỡng, cập nhật kiến thức mới nhằm nâng cao trình độ về mọi mặt, đáp ứng yêu cầu, nhiệm vụ. | G19: 2
A20: 1.5 | B20: Có phẩm chất đạo đức, lối sống trong sáng, trung thực, khiêm tốn, chân thành, giản dị; cần, kiệm, liêm, chính, chí công vô tư; chấp hành nghiêm quy định về chuẩn mực đạo đức cách mạng của cán bộ, đảng viên trong giai đoạn mới, trách nhiệm nêu gương; không vi phạm Quy định về những điều đảng viên không được làm. Không né tránh công việc, chạy theo thành tích; không vi phạm đạo đức, lối sống đến mức bị xử lý kỷ luật. | G20: 2
A21: 1.6 | B21: Không tham vọng quyền lực; không chạy chức, chạy quyền; không tham nhũng, lãng phí, cơ hội, vụ lợi, cục bộ, lợi ích nhóm; không để gia đình, người thân và người khác lợi dụng chức vụ, vị trí công tác để trục lợi. Không có biểu hiện suy thoái về tư tưởng chính trị, đạo đức, lối sống, những biểu hiện "tự diễn biến", "tự chuyển hoá" trong nội bộ. Kiên quyết đấu tranh chống quan liêu, cửa quyền, tham nhũng, xa hoa, lãng phí, tiêu cực, chủ nghĩa cá nhân, lối sống cơ hội, thực dụng, bè phái, lợi ích nhóm, nói không đi đôi với làm. | G21: 2
A22: 1.7 | B22: Có uy tín cao, tiêu biểu về phẩm chất đạo đức và phong cách công tác; là trung tâm đoàn kết, thương yêu đồng chí, đồng nghiệp. | G22: 2
A23: 1.8 | B23: Có tinh thần chủ động, đổi mới sáng tạo; phấn đấu vì mục tiêu phát triển của cơ quan, đơn vị, đóng góp vào mục tiêu chung của đất nước. | G23: 2
A24: 1.9 | B24: Thực hiện việc kê khai và công khai tài sản, thu nhập theo quy định. Báo cáo đầy đủ, trung thực, cung cấp thông tin chính xác, khách quan về những nội dung liên quan đến việc thực hiện chức trách, nhiệm vụ được giao và hoạt động của cơ quan, tổ chức, đơn vị với cấp trên khi được yêu cầu. | G24: 2
A25: 2 | B25: Tư duy đổi mới, chiến lược, khát vọng cống hiến, dám nghĩ dám làm | G25: =SUM(G26:G29) -> 4 | H25: =SUM(H26:H29) -> 0
A26: 2.1 | B26: Có tư duy đổi mới, tầm nhìn chiến lược, khả năng lãnh đạo, chỉ đạo thích ứng với sự phát triển của thời đại và xu thế toàn cầu hoá; phương pháp làm việc khoa học, nhạy bén chính trị; có năng lực cụ thể hoá trong lãnh đạo, chỉ đạo cơ quan, đơn vị thực hiện và hoàn thành tốt chức năng, nhiệm vụ được giao. | G26: 1
A27: 2.2 | B27: Luôn bám sát thực tiễn, có nhiều cách làm hay, sáng tạo, đạt hiệu quả cao trong lãnh đạo, chỉ đạo, tổ chức thực hiện nhiệm vụ; xây dựng cấp uỷ, tổ chức đảng trong sạch, vững mạnh, cơ quan, đơn vị vững mạnh toàn diện. | G27: 1
A28: 2.3 | B28: Nói đi đôi với làm, dám nghĩ, dám làm, dám chịu trách nhiệm, dám đột phá vì lợi ích chung. Có khả năng phân tích, dự báo tình hình, phát hiện những khó khăn, bất cập, thời cơ, thuận lợi trong thực tiễn; đề xuất hoặc quyết định những giải pháp phù hợp, kịp thời, hiệu quả. | G28: 1
A29: 2.4 | B29: Có khát vọng phấn đấu, cống hiến; có khả năng quy tụ và phát huy được sức mạnh của tập thể, cá nhân trong cơ quan, đơn vị và các cơ quan, đơn vị có liên quan. | G29: 1
A30: 3 | B30: Về tự phê bình và phê bình, tự soi, tự sửa, khắc phục hạn chế, khuyết điểm | G30: =SUM(G31:G34) -> 8 | H30: =SUM(H31:H34) -> 0
A31: 3.1 | B31: Chủ động, nghiêm túc thực hiện tự phê bình và phê bình, có tinh thần cầu thị và tiếp thu phản biện, góp ý. | G31: 2
A32: 3.2 | B32: Có kế hoạch rõ ràng và quyết liệt trong khắc phục hạn chế, khuyết điểm đã được chỉ ra. | G32: 2
A33: 3.3 | B33: Kết quả khắc phục hoàn thành từ ≥ 80% nội dung, có tiến bộ rõ, được tổ chức đánh giá tốt; không để tái diễn tồn tại. | G33: 2
A34: 3.4 | B34: Tự soi, tự sửa trên tinh thần trách nhiệm chính trị cao, không né tránh, không đổ lỗi. | G34: 2
A35: Tổng (A) = | G35: =SUM(G30,G25,G15) -> 30 | H35: =SUM(H15,H25,H30,) -> 0
A36: B | B36: KẾT QUẢ THỰC HIỆN NHIỆM VỤ ĐƯỢC GIAO (70 ĐIỂM)
B37: Tập trung vào các trục kết quả trọng tâm: (1) Thực hiện mục tiêu phát triển kinh tế - xã hội và nhiệm vụ chính trị được giao; (2) Hoàn thiện thể chế, đẩy mạnh phân cấp, phân quyền gắn với kiểm tra, giám sát; (3) Thúc đẩy phát triển khoa học, công nghệ, đổi mới sáng tạo và chuyển đổi số; (4) Xây dựng Đảng và hệ thống chính trị trong sạch, vững mạnh; giữ gìn đoàn kết, thống nhất nội bộ; phòng, chống tham nhũng, lãng phí, tiêu cực; (5) Phát triển văn hóa, con người, bảo đảm an sinh xã hội, nâng cao đời sống nhân dân; (6) Củng cố quốc phòng, an ninh, giữ vững ổn định chính trị - xã hội, nâng cao hiệu quả đối ngoại và hội nhập quốc tế. | G37: Điểm tối đa (70 điểm) | H37: Điểm đạt được = Điểm KPI đã tính tại bảng tính điểm | I37: Ghi chú
A38: TỔNG (B) = Điểm KPI đã tính tại bảng tính điểm | G38: 70 | H38: ='2 - BẢNG TÍNH KPI '!C79 -> #DIV/0!
A40: TỔNG (A+ B) = | G40: =G38+G35 -> 100 | H40: =H35+H38 -> #DIV/0!
B41: II. Tự đề xuất xếp loại mức chất lượng:…................................................................................................................................................................................
...

Sheet BẢNG TÍNH ĐIỂM (2)
A1: BẢNG TÍNH ĐIỂM KPI (Cách 2: chia nhỏ 6 trục, tính KPI trên điểm từng trục tại phần II, Bản tự đánh giá cá nhân KPI từng sản phẩm =Điểm chuẩn*(30% Tiến độ %+70% Chất lượng%))
A2: TT | B2: Tên công việc | C2: Điểm chuẩn | D2: Hệ số độ khó | E2: Tiến độ % | F2: Kết quả % | G2: Điểm thực hiện | H2: Điểm quy đổi
A3: 1 | B3: 2 | C3: (3) = Điểm chuẩn của công việc được xác định tại Danh mục Sản phẩm chuẩn | D3: (4) = HSĐK của công việc được xác định tại Danh mục Sản phẩm chuẩn | E3: (5) Căn cứ theo thời hạn hoàn thành + Hoàn thành đúng hoặc trước hạn: 100%; + Hoàn thành chậm 1– 3 ngày làm việc: 80%; + Hoàn thành chậm 4 – 5 ngày làm việc: 60%; + Hoàn thành chậm trên 5 ngày làm việc: 0%. | F3: (6) Căn cứ chất lượng sản phẩm + Đạt đầy đủ yêu cầu: 100%; + Đạt yêu cầu, chỉnh sửa nhỏ: 80%; + Hoàn thành cơ bản: 60%; + Không đạt yêu cầu: 0%. | G3: (7) = (3) * (30% (5)+70%(6)) | H3: (8) = (7)*(4)
A4: I | B4: Trục (1) - THỰC HIỆN MỤC TIÊU PHÁT TRIỂN KINH TẾ - XÃ HỘI VÀ NHIỆM VỤ CHÍNH TRỊ ĐƯỢC GIAO
A5: 2 | B5: Công văn số 1506-CV/BTCTU ngày 23/4/2026 rà soát các khoản chi thường xuyên để điều chỉnh dự toán ngân sách nhà nước năm 2026 (Công văn số 2846-CV/VPTU ngày 17/4/2026) (trước hạn, đạt đầy đủ yêu cầu) | C5: =#REF! -> #REF! | D5: =#REF! -> #REF! | E5: 1 | F5: 1 | G5: =C5*(30%*E5+70%*F5) -> #REF! | H5: =D5*G5 -> #REF!
B6: Tổng điểm A trục 1 | C6: =SUM(C5) -> #REF! | F6: Tổng điểm B trục 1 | H6: =MIN(SUM(H5),C6) -> #REF!
B7: KPI % (trục 1) = B/A (nếu không có nhiệm vụ thì KPI được trọn 100%) | C7: =H6/C6 -> #REF! | D7: (Điểm % này được sử dụng để đưa vào cột Điểm KPI (%) tại trục 1, phần II, mẫu 1. Bản tự nhận xét, đánh giá của cá nhân)
A8: II | B8: Trục (2) - HOÀN THIỆN THỂ CHẾ, ĐẨY MẠNH PHÂN CẤP, PHÂN QUYỀN GẮN VỚI KIỂM TRA, GIÁM SÁT
B10: Tổng điểm A trục 2 | C10: =SUM(C9) -> 0 | F10: Tổng điểm B trục 2 | H10: =MIN(SUM(H9),C10) -> 0
B11: KPI % (trục 2) = B/A (nếu không có nhiệm vụ thì KPI được trọn 100%) | C11: =IF(C9=0,1,H9/C9) -> 1 | D11: (Điểm % này được sử dụng để đưa vào cột Điểm KPI (%) tại trục 2, phần II, mẫu 1. Bản tự nhận xét, đánh giá của cá nhân)
A13: III | B13: THÚC ĐẨY PHÁT TRIỂN KHOA HỌC, CÔNG NGHỆ, ĐỔI MỚI SÁNG TẠO VÀ CHUYỂN ĐỔI SỐ
A14: 8 | B14: Công văn số 1461-CV/BTCTU ngày 20/4/2026 về khai thác dữ liệu văn bản điện tử không mật của Thành phố Hồ Chí Minh (cũ), Tỉnh Bình Dương, Tỉnh Bà Rịa - Vũng Tàu trước sáp nhập (Công văn số 2519-CV/VPTU ngày 30/3/2026) (trước hạn, đạt yêu cầu, chỉnh sửa nhỏ) | C14: =#REF! -> #REF! | D14: =#REF! -> #REF! | E14: 1 | F14: 0.8 | G14: =C14*(30%*E14+70%*F14) -> #REF! | H14: =D14*G14 -> #REF!
B15: Tổng điểm A trục 3 | C15: =SUM(C14) -> #REF! | F15: Tổng điểm B trục 3 | H15: =MIN(SUM(H14),C15) -> #REF!
B16: KPI % (trục 3) = B/A (nếu không có nhiệm vụ thì KPI được trọn 100%) | C16: =IF(C14=0,1,H14/C14) -> #REF! | D16: (Điểm % này được sử dụng để đưa vào cột Điểm KPI (%) tại trục 3, phần II, mẫu 1. Bản tự nhận xét, đánh giá của cá nhân)
A17: IV | B17: (4) - XÂY DỰNG ĐẢNG VÀ HỆ THỐNG CHÍNH TRỊ TRONG SẠCH, VỮNG MẠNH; GIỮ GÌN ĐOÀN KẾT, THỐNG NHẤT NỘI BỘ; PHÒNG, CHỐNG THAM NHŨNG, LÃNG PHÍ, TIÊU CỰC
A18: 2 | B18: Kế hoạch số 54-KH/TU ngày 06/4/2026 rà soát, bổ sung quy hoạch nguồn Thành ủy khóa I và cán bộ lãnh đạo, quản lý thuộc Thành ủy khóa I, nhiệm kỳ 2025-2030 (trễ hạn >=5 ngày, đạt yêu cầu, chỉnh sửa nhỏ) | C18: =#REF! -> #REF! | D18: =#REF! -> #REF! | E18: 0 | F18: 0.8 | G18: =C18*(30%*E18+70%*F18) -> #REF! | H18: =D18*G18 -> #REF!
A19: 7 | B19: Công văn số 1410-CV/BTCTU ngày 14/4/2026 hỗ trợ, cung cấp thông tin quy hoạch các cá nhân thuộc diện Ban Thường vụ Thành ủy quản lý (Công văn số 1706/TTTP-TCCB ngày 09/4/2026 của Thanh tra Thành phố) (trễ hạn >=5 ngày, đạt đầy đủ yêu cầu ) | C19: =#REF! -> #REF! | D19: =#REF! -> #REF! | E19: 0 | F19: 1 | G19: =C19*(30%*E19+70%*F19) -> #REF! | H19: =D19*G19 -> #REF!
A20: 13 | B20: Công văn số 294-CV/TU ngày 22/4/2026 triển khai Kết luận số 12-KL/TW, ngày 19/3/2026 của Bộ Chính trị về kết quả kiểm điểm, đánh giá, xếp loại chất lượng đối với tập thể, cá nhân ban thường vụ các tỉnh ủy, thành ủy, đảng ủy trực thuộc Trung ương; tập thể, cá nhân cán bộ lãnh đạo, quản lý các cơ quan, đơn vị ở Trung ương năm 2025 (Phiếu chuyển số 410-PC/VPTU ngày 27/3/2026) (trước hạn, đạt đầy đủ yêu cầu) | C20: =#REF! -> #REF! | D20: =#REF! -> #REF! | E20: 1 | F20: 1 | G20: =C20*(30%*E20+70%*F20) -> #REF! | H20: =D20*G20 -> #REF!
A21: 14 | B21: Công văn số 251-CV/TU ngày 31/3/2026 chỉ đạo tiến hành rà soát, đánh giá tổng thể về số lượng, chất lượng đội ngũ cán bộ cơ sở, tổng hợp báo cáo Ban Thường vụ Thành ủy chất lượng đội ngũ cán bộ cơ sở (trước hạn, đạt đầy đủ yêu cầu) | C21: =#REF! -> #REF! | D21: =#REF! -> #REF! | E21: 1 | F21: 1 | G21: =C21*(30%*E21+70%*F21) -> #REF! | H21: =D21*G21 -> #REF!
A22: 16 | B22: Công văn số 295-CV/TU ngày 22/4/2026 thực hiện Kết luận số 16-KL/TW, ngày 31/3/2026 của Bộ Chính trị, Ban Bí thư về thực hiện một số nội dung, nhiệm vụ trọng tâm hoạt động của tổ chức cơ sở đảng trong quý II năm 2026 (Phiếu chuyển số 473-PC/VPTU ngay 03/4/2026) (trễ hạn 4-5 ngày, đạt đầy đủ yêu cầu) | C22: =#REF! -> #REF! | D22: =#REF! -> #REF! | E22: 0.6 | F22: 1 | G22: =C22*(30%*E22+70%*F22) -> #REF! | H22: =D22*G22 -> #REF!
A23: 17 | B23: Kế hoạch số 62-KH/TU ngày 22/4/2026 tổ chức tiếp Đoàn khảo sát về công tác xây dựng, chỉnh đốn Đảng và hệ thống chính trị; củng cố, nâng cao chất lượng tổ chức đảng và đội ngũ đảng viên (Kế hoạch số 21-KH/BTCTTW ngày 15/4/2026, Phiếu chuyển 559-PC/VPTU ngày 16/4/2026) (đúng hạn, đạt đầy đủ yêu cầu) | C23: =#REF! -> #REF! | D23: =#REF! -> #REF! | E23: 1 | F23: 1 | G23: =C23*(30%*E23+70%*F23) -> #REF! | H23: =D23*G23 -> #REF!
A24: 23 | B24: Nghị quyết số 09-NQ/TU ngày 14/4/42026 của Ban Thường vụ Thành ủy về giải pháp nâng cao chất lượng cán bộ cơ sở; bảo đảm mọi giải pháp đều có cơ chế theo dõi, kiểm tra, phản hồi và chịu trách nhiệm (Công văn số 251-CV/TU ngày 31/3/2026) (đúng hạn, đạt đầy đủ yêu cầu) | C24: =#REF! -> #REF! | D24: =#REF! -> #REF! | E24: 1 | F24: 1 | G24: =C24*(30%*E24+70%*F24) -> #REF! | H24: =D24*G24 -> #REF!
A25: 39 | B25: Quyết định số 790-QĐ/TU ngày 22/4/2026 tham mưu cử cán bộ đi nghiên cứu, khảo sát tại Trung Quốc (Công văn số 508-CV/BTCTW ngày 03/4/2026, Phiếu chuyển 482-PC/VPTU ngày 06/4/2026) (đúng hạn, đạt yêu cầu, chỉnh sửa nhỏ) | C25: =#REF! -> #REF! | D25: =#REF! -> #REF! | E25: 1 | F25: 0.8 | G25: =C25*(30%*E25+70%*F25) -> #REF! | H25: =D25*G25 -> #REF!
A26: 40 | B26: Tờ trình số 539-TTr/BTCTU ngày 21/4/2026 về cử cán bộ tham gia khóa bồi dưỡng ngắn hạn tại Nhật Bản (Công văn số 10-CV/BCĐ ngày 31/3/2026 của Ban Chỉ đạo các chương trình đào tạo, bồi dưỡng nước ngoài Trung ương) (đúng hạn, đạt đầy đủ yêu cầu) | C26: =#REF! -> #REF! | D26: =#REF! -> #REF! | E26: 1 | F26: 1 | G26: =C26*(30%*E26+70%*F26) -> #REF! | H26: =D26*G26 -> #REF!
A27: 53 | B27: Công văn số 1308-CV/BTCTU ngày 31/3/2026 xác minh hồ sơ và đề nghị xử lý kỷ luật Đảng viên vi phạm - Hoàng Xuân Tuấn (Công văn số 7970/CQCSĐT, 25/3/2026 của Cơ quan CSĐT CA.TPHCM) (trễ hạn 1 ngày, đạt đầy đủ yêu cầu) | C27: =#REF! -> #REF! | D27: =#REF! -> #REF! | E27: 0.8 | F27: 1 | G27: =C27*(30%*E27+70%*F27) -> #REF! | H27: =D27*G27 -> #REF!
A28: 56 | B28: Công văn số 1441-CV/BTCTU ngày 17/4/2026 hướng dẫn rà soát, quy hoạch cán bộ năm 2026 đối với người giữ chức danh, chức vụ quản lý trong doanh nghiệp do Nhà nước nắm giữ 100% vốn điều lệ thuộc Ủy ban nhân dân Thành phố (Công văn số 5812/SNV ngày 09/4/2026 (trước hạn, đạt đầy đủ yêu cầu) | C28: =#REF! -> #REF! | D28: =#REF! -> #REF! | E28: 1 | F28: 1 | G28: =C28*(30%*E28+70%*F28) -> #REF! | H28: =D28*G28 -> #REF!
A29: 61 | B29: Công văn số 1496-CV/BTCTU ngày 22/4/2026 báo cáo kinh phí mua vé máy bay đi công tác nước ngoài cho một số chức danh lãnh đạo của Thành phố (Công văn số 2731-CV/VPTU ngày 10/4/2026) (đúng hạn, đạt đầy đủ yêu cầu) | C29: =#REF! -> #REF! | D29: =#REF! -> #REF! | E29: 1 | F29: 1 | G29: =C29*(30%*E29+70%*F29) -> #REF! | H29: =D29*G29 -> #REF!
A30: 66 | B30: Công văn số 1459-CV/BTCTU ngày 20/4/2026 cử cán bộ tham gia Đoàn kiểm tra việc lãnh đạo, chỉ đạo và tổ chức thực hiện Kết luận số 89-KL/TW (Công văn số 1234-CV/BTGDVTU ngày 16 tháng 4 năm 2026) (trễ hạn >=5 ngày, đạt đầy đủ yêu cầu) | C30: =#REF! -> #REF! | D30: =#REF! -> #REF! | E30: 0 | F30: 1 | G30: =C30*(30%*E30+70%*F30) -> #REF! | H30: =D30*G30 -> #REF!
A31: 68 | B31: Công văn số 1496-CV/BTCTU ngày 22/4/2026 báo cáo kinh phí mua vé máy bay đi công tác nước ngoài cho một số chức danh lãnh đạo của Thành phố (Công văn số 2731-CV/VPTU ngày 10/4/2026) (đúng hạn, đạt đầy đủ yêu cầu) | C31: =#REF! -> #REF! | D31: =#REF! -> #REF! | E31: Theo yêu cầu của cấp thẩm quyền | F31: 1 | G31: 1 | H31: =D31*G31 -> #REF!
A32: 78 | B32: Công văn số 303-CV/TU ngày 30/4/2026 góp ý các dự thảo bổ sung, sửa đổi quy định, quyết định của Ban Bí thư (Quy định số 60-QĐ/TW và Quyết định số 61-QĐ/TW) - Công văn số 722-CV/BTCTW ngày 25/4/2026 (trễ hạn1 ngày, đạt yêu cầu, chỉnh sửa nhỏ) | C32: =#REF! -> #REF! | D32: =#REF! -> #REF! | E32: 1 | F32: 0.8 | G32: =C32*(30%*E32+70%*F32) -> #REF! | H32: =D32*G32 -> #REF!
A33: 86 | B33: Công văn số 340-CV/TU ngày 21/5/2026 góp ý các dự thảo quy định của Ban Bí thư về chức năng, nhiệm vụ, tổ chức bộ máy, mối quan hệ công tác của tổ chức đảng trong các cơ sở giáo dục đại học công lập theo Công văn số 788-CV/BTCTW ngày 05/5/2026 (Công văn số 3176-CV/VPTU ngày 06/5/2026) (trước hạn, đạt đầy đủ yêu cầu) | C33: =#REF! -> #REF! | D33: =#REF! -> #REF! | E33: 1 | F33: 1 | G33: =C33*(30%*E33+70%*F33) -> #REF! | H33: =D33*G33 -> #REF!
A34: 88 | B34: Tham mưu góp ý hồ sơ dự thảo quyết định của UBND Thành phố ban hành quy định về kiểm điểm, dánh giá, xếp loại chất lượng đối với cơ quan hành chính Nhà nước và công chức trên địa bàn TPHCM (đúng hạn, đạt đầy đủ yêu cầu) | C34: =#REF! -> #REF! | D34: =#REF! -> #REF! | E34: 1 | F34: 1 | G34: =C34*(30%*E34+70%*F34) -> #REF! | H34: =D34*G34 -> #REF!
A35: 94 | B35: Công văn số 337-CV/TU ngày 19/5/2026 góp ý dự thảo Hướng dẫn nội dung chương trình bồi dưỡng thuộc chức năng, nhiệm vụ của trường chính trị giai đoạn 2026-2030 theo Công văn số 901-CV/HVCTQG ngày 04/5/2026 (Phiếu chuyển số 664-PC/VPTU ngày 05/5/2026) (đúng hạn, đạt đầy đủ yêu cầu) | C35: =#REF! -> #REF! | D35: =#REF! -> #REF! | E35: 1 | F35: 1 | G35: =C35*(30%*E35+70%*F35) -> #REF! | H35: =D35*G35 -> #REF!
A36: 95 | B36: Công văn số 333-CV/TU ngày 18/5/2026 góp ý dự thảo Kết luận của Ban Bí thư về tiếp tục thực hiện Chỉ thị số 33-CT/TW, ngày 18/3/2019 của Ban Bí thư về tăng cường xây dựng tổ chức đảng trong các đơn vị kinh tế tư nhân (Phiếu chuyển số 727-PC/VPTU ngày 13/5/2026) (trễ hạn 4 ngày, đạt đầy đủ yêu cầu) | C36: =#REF! -> #REF! | D36: =#REF! -> #REF! | E36: 0.6 | F36: 1 | G36: =C36*(30%*E36+70%*F36) -> #REF! | H36: =D36*G36 -> #REF!
A37: 105 | B37: Công văn số 340-CV/TU ngày 21/5/2026 góp ý dự thảo Quy phối hợp công tác giữa đảng ủy bộ, ngành Trung ương với cấp ủy cấp trên trực tiếp của tổ chức đảng trong cơ sở giáo dục đại học công lập (Công văn số 871-CV/BTCTW ngày 12/5/2026 của Ban Tổ chức Trung ương) (trước hạn, đạt đầy đủ yêu cầu) | C37: =#REF! -> #REF! | D37: =#REF! -> #REF! | E37: 1 | F37: 1 | G37: =C37*(30%*E37+70%*F37) -> #REF! | H37: =D37*G37 -> #REF!
A38: 108 | B38: Quyết định số 821-QĐ/TU ngày 22/5/2026 tạm giao biên chế năm 2026 của Khối Đảng, Cơ quan Mặt trận Tổ quốc Việt Nam Thành phố; khối Đảng, cơ quan Ủy ban Mặt trận Tổ quốc Việt Nam xã, phường, đặc khu năm 2026 để tiếp nhận một số cán bộ không chuyên trách đủ điều kiện vào công chức (trễ hạn 3ngày, đạt yêu cầu, chỉnh sửa nhỏ) | C38: =#REF! -> #REF! | D38: =#REF! -> #REF! | E38: 0.8 | F38: 0.8 | G38: =C38*(30%*E38+70%*F38) -> #REF! | H38: =D38*G38 -> #REF!
A39: 115 | B39: Công văn số 1771-CV/BTCTU ngày 18/5/2026 Hướng dẫn xây dựng Đề án vị trí việc làm công chức, viên chức (trễ hạn 1 ngày, đạt đầy đủ yêu cầu) | C39: =#REF! -> #REF! | D39: =#REF! -> #REF! | E39: 0.8 | F39: 1 | G39: =C39*(30%*E39+70%*F39) -> #REF! | H39: =D39*G39 -> #REF!
A40: 131 | B40: Tờ trình số 648-TTr/BTCTU ngày 24/5/2026 báo cáo chuyên đề những điểm mới, mô hình, sáng kiến, cách làm hiệu quả, kết quả nổi bật của TP.HCM sau 1 năm vận hành chính quyền địa phương 2 cấp; đề xuất, kiến nghị (Công văn số 341-CV/TU ngày 21/5/2026) (đúng hạn, đạt đầy đủ yêu cầu) | C40: =#REF! -> #REF! | D40: =#REF! -> #REF! | E40: 1 | F40: 1 | G40: =C40*(30%*E40+70%*F40) -> #REF! | H40: =D40*G40 -> #REF!
A41: 132 | B41: Tờ trình số 648-TTr/BTCTU ngày 24/5/2026 Tờ trình số 6454TTr/BTCTU ngày 27/5/2026 về dự thảo Báo cáo của Ban Thường vụ Thành ủy về sơ kết 01 năm vận hành bộ máy của hệ thống chính trị và chính quyền địa phương 2 (Kế hoạch số 73-KH/TU ngày 19/5/2026) (trễ hạn 1 ngày, đạt đầy đủ yêu cầu) | C41: =#REF! -> #REF! | D41: =#REF! -> #REF! | E41: 0.8 | F41: 1 | G41: =C41*(30%*E41+70%*F41) -> #REF! | H41: =D41*G41 -> #REF!
A42: 147 | B42: Công văn số 1563-CV/BTCTU ngày 29/4/2026 phúc đáp Công văn số 451/SNV- TCBC&TCPCP ngày 21/4/2026 của Sở Nội vụ (đúng hạn, đạt đầy đủ yêu cầu) | C42: =#REF! -> #REF! | D42: =#REF! -> #REF! | E42: 1 | F42: 1 | G42: =C42*(30%*E42+70%*F42) -> #REF! | H42: =D42*G42 -> #REF!
...

Sheet ĐẢNG, ĐOÀN THỂ (2)
A1: GỢI Ý KHUNG CHẤM ĐIỂM ĐÁNH GIÁ ĐỐI VỚI CÁN BỘ LÃNH ĐẠO, QUẢN LÝ KHỐI ĐẢNG, ĐOÀN THỂ TRÊN CƠ SỞ CỤ THỂ HOÁ THEO MẪU 5,HƯỚNG DẪN SỐ 43-HD/BTCTW CỦA BAN TỔ CHỨC TRUNG ƯƠNG (kèm theo Hướng dẫn số -HD/BTCTU, ngày tháng 6 năm 2026)
H2: Mẫu 01-Đ,ĐT
A3: TỈNH UỶ/THÀNH UỶ/ĐẢNG UỶ/ CƠ QUAN, ĐƠN VỊ… * | F3: ĐẢNG CỘNG SẢN VIỆT NAM
F4: …..., ngày…… tháng… … năm……
A5: BẢN TỰ ĐÁNH GIÁ, XẾP LOẠI CỦA CÁ NHÂN (Cách 2: chia nhỏ 6 trục, tính KPI trên điểm từng trục tại phần II, Bản tự đánh giá cá nhân KPI từng sản phẩm =Điểm chuẩn*(30% Tiến độ %+70% Chất lượng%))
A6: Quý II, Năm 2026
B7: Họ và tên: Thái Thị Bích Liên Ngày sinh: 10/4/1973
B8: Chức vụ Đảng: Thành ủy viên
B9: Chức vụ chính quyền: Phó trưởng ban Thường trực Ban Tổ chức Thành ủy
B10: Chức vụ đoàn thể: Không có
B11: Đơn vị công tác: Ban Tổ chức Thành ủy
B12: I. Tự đánh giá kết quả thực hiện nhiệm vụ
B13: Trên cơ sở nhiệm vụ được giao, cá nhân tự đánh giá về kết quả thực hiện nhiệm vụ theo quý như sau:
A14: I | B14: NHÓM TIÊU CHÍ CHUNG (30 ĐIỂM) - Các tiêu chí thực hiện theo Quy định sô 366-QĐ/TW của Bộ Chính trị
A15: TT | B15: Tiêu chí / Nội dung | E15: Đảm bảo (Đánh dấu x) | F15: Không đảm bảo (Đánh dấu x) | G15: Điểm tối đa | H15: Điểm đạt (Chấm tối đa nếu đảm bảo; Chấm 0 điểm nếu không đảm bảo) | I15: Ghi chú
A16: 1 | B16: Về phẩm chất chính trị, đạo đức, lối sống, thực hiện trách nhiệm nêu gương | G16: =SUM(G17:G25) -> 18 | H16: =SUM(H17:H25) -> 18
A17: 1.1 | B17: Tuyệt đối trung thành với Đảng, Tổ quốc và Nhân dân; kiên định chủ nghĩa Mác - Lênin, tư tưởng Hồ Chí Minh, mục tiêu độc lập dân tộc và chủ nghĩa xã hội. Có lập trường, quan điểm, bản lĩnh chính trị vững vàng; kiên quyết bảo vệ nền tảng tư tưởng, Cương lĩnh chính trị, đường lối của Đảng, Hiến pháp, pháp luật của Nhà nước; đấu tranh phản bác các quan điểm sai trái, thù địch, các biểu hiện suy thoái, "tự diễn biến", "tự chuyển hoá". | G17: 2 | H17: 2
A18: 1.2 | B18: Có tinh thần yêu nước sâu sắc, tận tuỵ phục vụ Nhân dân, sâu sát cơ sở, luôn hành động vì lợi ích của Nhân dân. Đặt lợi ích của Đảng, quốc gia - dân tộc, Nhân dân, tập thể lên trên lợi ích cá nhân, sẵn sàng hy sinh vì sự nghiệp cách mạng của Đảng, vì độc lập, tự do của Tổ quốc, vì hạnh phúc của Nhân dân. | G18: 2 | H18: 2
A19: 1.3 | B19: Chấp hành nghiêm chủ trương, đường lối, nghị quyết, chỉ thị, quy định, nguyên tắc tổ chức, kỷ luật của Đảng, nhất là nguyên tắc tập trung dân chủ, tự phê bình và phê bình; chấp hành nghiêm pháp luật của Nhà nước và quy định của cơ quan, đơn vị. Tuyệt đối chấp hành sự phân công của tổ chức, yên tâm công tác và hoàn thành tốt mọi nhiệm vụ được giao. | G19: 2 | H19: 2
A20: 1.4 | B20: Có tinh thần tự giác, trách nhiệm cao trong nghiên cứu, học tập chủ nghĩa Mác - Lênin, tư tưởng Hồ Chí Minh, các nghị quyết, chỉ thị của Đảng và các chương trình bồi dưỡng, cập nhật kiến thức mới nhằm nâng cao trình độ về mọi mặt, đáp ứng yêu cầu, nhiệm vụ. | G20: 2 | H20: 2
A21: 1.5 | B21: Có phẩm chất đạo đức, lối sống trong sáng, trung thực, khiêm tốn, chân thành, giản dị; cần, kiệm, liêm, chính, chí công vô tư; chấp hành nghiêm quy định về chuẩn mực đạo đức cách mạng của cán bộ, đảng viên trong giai đoạn mới, trách nhiệm nêu gương; không vi phạm Quy định về những điều đảng viên không được làm. Không né tránh công việc, chạy theo thành tích; không vi phạm đạo đức, lối sống đến mức bị xử lý kỷ luật. | G21: 2 | H21: 2
A22: 1.6 | B22: Không tham vọng quyền lực; không chạy chức, chạy quyền; không tham nhũng, lãng phí, cơ hội, vụ lợi, cục bộ, lợi ích nhóm; không để gia đình, người thân và người khác lợi dụng chức vụ, vị trí công tác để trục lợi. Không có biểu hiện suy thoái về tư tưởng chính trị, đạo đức, lối sống, những biểu hiện "tự diễn biến", "tự chuyển hoá" trong nội bộ. Kiên quyết đấu tranh chống quan liêu, cửa quyền, tham nhũng, xa hoa, lãng phí, tiêu cực, chủ nghĩa cá nhân, lối sống cơ hội, thực dụng, bè phái, lợi ích nhóm, nói không đi đôi với làm. | G22: 2 | H22: 2
A23: 1.7 | B23: Có uy tín cao, tiêu biểu về phẩm chất đạo đức và phong cách công tác; là trung tâm đoàn kết, thương yêu đồng chí, đồng nghiệp. | G23: 2 | H23: 2
A24: 1.8 | B24: Có tinh thần chủ động, đổi mới sáng tạo; phấn đấu vì mục tiêu phát triển của cơ quan, đơn vị, đóng góp vào mục tiêu chung của đất nước. | G24: 2 | H24: 2
A25: 1.9 | B25: Thực hiện việc kê khai và công khai tài sản, thu nhập theo quy định. Báo cáo đầy đủ, trung thực, cung cấp thông tin chính xác, khách quan về những nội dung liên quan đến việc thực hiện chức trách, nhiệm vụ được giao và hoạt động của cơ quan, tổ chức, đơn vị với cấp trên khi được yêu cầu. | G25: 2 | H25: 2
A26: 2 | B26: Tư duy đổi mới, chiến lược, khát vọng cống hiến, dám nghĩ, dám làm | G26: =SUM(G27:G30) -> 4 | H26: =SUM(H27:H30) -> 4
A27: 2.1 | B27: Có tư duy đổi mới, tầm nhìn chiến lược, khả năng lãnh đạo, chỉ đạo thích ứng với sự phát triển của thời đại và xu thế toàn cầu hoá; phương pháp làm việc khoa học, nhạy bén chính trị; có năng lực cụ thể hoá trong lãnh đạo, chỉ đạo cơ quan, đơn vị thực hiện và hoàn thành tốt chức năng, nhiệm vụ được giao. | G27: 1 | H27: 1
A28: 2.2 | B28: Luôn bám sát thực tiễn, có nhiều cách làm hay, sáng tạo, đạt hiệu quả cao trong lãnh đạo, chỉ đạo, tổ chức thực hiện nhiệm vụ; xây dựng cấp uỷ, tổ chức đảng trong sạch, vững mạnh, cơ quan, đơn vị vững mạnh toàn diện. | G28: 1 | H28: 1
A29: 2.3 | B29: Nói đi đôi với làm, dám nghĩ, dám làm, dám chịu trách nhiệm, dám đột phá vì lợi ích chung. Có khả năng phân tích, dự báo tình hình, phát hiện những khó khăn, bất cập, thời cơ, thuận lợi trong thực tiễn; đề xuất hoặc quyết định những giải pháp phù hợp, kịp thời, hiệu quả. | G29: 1 | H29: 1
A30: 2.4 | B30: Có khát vọng phấn đấu, cống hiến; có khả năng quy tụ và phát huy được sức mạnh của tập thể, cá nhân trong cơ quan, đơn vị và các cơ quan, đơn vị có liên quan. | G30: 1 | H30: 1
B31: 3. Về tự phê bình và phê bình, tự soi, tự sửa, khắc phục hạn chế, khuyết điểm | G31: =SUM(G32:G35) -> 8 | H31: =SUM(H32:H35) -> 8
A32: 3.1 | B32: Chủ động, nghiêm túc thực hiện tự phê bình và phê bình, có tinh thần cầu thị và tiếp thu phản biện, góp ý. | G32: 2 | H32: 2
A33: 3.2 | B33: Có kế hoạch rõ ràng và quyết liệt trong khắc phục hạn chế, khuyết điểm đã được chỉ ra. | G33: 2 | H33: 2
A34: 3.3 | B34: Kết quả khắc phục hoàn thành từ ≥ 80% nội dung, có tiến bộ rõ, được tổ chức đánh giá tốt; không để tái diễn tồn tại. | G34: 2 | H34: 2
A35: 3.4 | B35: Tự soi, tự sửa trên tinh thần trách nhiệm chính trị cao, không né tránh, không đổ lỗi. | G35: 2 | H35: 2
A36: Tổng (A) = | G36: =SUM(G31,G26,G16) -> 30 | H36: =SUM(H31,H26,H16) -> 30
A37: B | B37: KẾT QUẢ THỰC HIỆN NHIỆM VỤ ĐƯỢC GIAO (70 ĐIỂM)
A38: TT | B38: Tiêu chí / Nội dung | D38: Mục tiêu, nhiệm vụ đề ra | E38: Kết quả sản phẩm thực tế | F38: Điểm KPI (%) | G38: Điểm tối đa | H38: Điểm đạt (= Điểm KPI x Điểm tối đa) | I38: Ghi chú
A39: 1 | B39: Trục (1) - THỰC HIỆN MỤC TIÊU PHÁT TRIỂN KINH TẾ - XÃ HỘI VÀ NHIỆM VỤ CHÍNH TRỊ ĐƯỢC GIAO (10 ĐIỂM) - Lãnh đạo, chỉ đạo, điều hành, tổ chức thực hiện hiệu quả nghị quyết, chỉ thị, kết luận, quy định, hướng dẫn của Trung ương và cấp trên. - Chủ động xây dựng và lãnh đạo, chỉ đạo thực hiện có hiệu quả kế hoạch, chương trình công tác, đề án, quy chế, quy định thuộc lĩnh vực phụ trách gắn với kế hoạch, chương trình công tác và tình hình thực tiễn của tổ chức, cơ quan, đơn vị. - Phân tích, tổng hợp, đánh giá và tham mưu cấp uỷ ban hành các văn bản theo lĩnh vực công tác đạt yêu cầu về nội dung, hình thức và tiến độ; - Các nội dung khác (nếu có) | D39: ='BẢNG TÍNH ĐIỂM (2)'!C6 -> #REF! | E39: ='BẢNG TÍNH ĐIỂM (2)'!H6 -> #REF! | F39: ='BẢNG TÍNH ĐIỂM (2)'!C7 -> #REF! | G39: 10 | H39: =F39*G39 -> #REF!
